Workbook

Sheet test case
A1: Test Case ID | B1: Title | C1: Preconditions | D1: Steps | E1: Expected Result | F1: Tester | G1: Priority | H1: Status
A2: TC-001 | B2: Đăng nhập hợp lệ | C2: Có tài khoản hợp lệ | D2: 1. Mở trang đăng nhập 2. Nhập username: haitv/ Nhập password: 1234haitv 3. Nhấn nút Đăng nhập | E2: Hệ thống hiển thị trang chủ | F2: Nguyễn Văn Hải | G2: P1 | H2: Ready
A3: TC-002 | B3: Đăng nhập sai mật khẩu | C3: Có tài khoản hợp lệ | D3: 1. Mở trang đăng nhập 2. Nhập username: haitv/Nhập password: 1234567890 3. Nhấn nút Đăng nhập | E3: Hệ thống hiển thị thông báo lỗi 'Sai mật khẩu' | F3: Nguyễn Văn Hải | G3: P2 | H3: Ready
B4: …
C10: Mức Priority | D10: Ý nghĩa | E10: Ví dụ
C11: P0 – Critical | D11: Phải kiểm thử ngay hoặc sửa lỗi khẩn cấp, ảnh hưởng nghiêm trọng đến hoạt động chính | E11: Không thể đăng nhập, không thể checkout
C12: P1 – High | D12: Ưu tiên cao, cần kiểm thử/sửa sớm vì ảnh hưởng đến chức năng chính | E12: Sai mật khẩu không báo lỗi, form đăng nhập không phản hồi
C13: P2 – Medium | D13: Quan trọng vừa phải, có thể làm sau các chức năng chính | E13: Thông báo lỗi hiển thị sai màu, căn lề không chuẩn
C14: P3 – Low | D14: Ưu tiên thấp, ít ảnh hưởng, có thể kiểm thử cuối cùng | E14: Giao diện lỗi chính tả, font chữ chưa đúng

Sheet Đăng ký
A1: Module Code | B1: Đăng ký
A2: Test requirement | B2: <Brief description about requirements which are tested in this sheet> | F2: rơ
A3: Tester
A4: Pass | B4: Fail | C4: Untested | D4: N/A | E4: Number of Test cases
A5: =COUNTIF(I6:I998,"Pass") -> 19 | B5: =COUNTIF(I6:I998,"Fail") -> 1 | C5: =E5-D5-A5-B5 -> 0 | D5: =COUNTIF(H$7:I$999,"N/A") -> 0 | E5: =COUNTA(A7:A1002) -> 20
A6: Test Case ID | B6: Group Name | C6: Sub Group Name | D6: Test Case Description | E6: Precondition | F6: Test Case Procedure | G6: Test data | H6: Expected Output | I6: Result | J6: Tester | K6: Priority | L6: Status
A7: ="TC-" & TEXT(ROW()-6,"000") -> TC-001 | B7: Access right | D7: Kiểm tra cách vào màn hình đăng ký | E7: Người dùng chưa có tài khoản | F7: 1. Truy cập website 2. Click “Đăng ký” | H7: 1. Hiển thị màn hình Đăng ký | I7: Pass | J7: Trần Thị Phương Thảo | K7: P1 | L7: Ready
A8: ="TC-" & TEXT(ROW()-6,"000") -> TC-002 | B8: UI | D8: Kiểm tra số lượng các item | F8: 1. Kiểm tra số lượng các item | H8: 1. Hiển thị đúng số lượng các item trên màn hình | I8: Pass | J8: Trần Thị Phương Thảo | K8: P2 | L8: Ready
A9: ="TC-" & TEXT(ROW()-6,"000") -> TC-003 | D9: Kiểm tra vị trí, font chữ, size chữ, màu sắc | F9: 1. Kiểm tra vị trí, font chữ, size chữ, màu sắc | H9: 1. Hiển thị đúng theo design | I9: Pass | J9: Trần Thị Phương Thảo | K9: P2 | L9: Ready
A10: ="TC-" & TEXT(ROW()-6,"000") -> TC-004 | D10: Kiểm tra trạng thái | F10: 1. Kiểm tra trạng thái các item | H10: 1. Các item đều ở trạng thái enable | I10: Pass | J10: Trần Thị Phương Thảo | K10: P2 | L10: Ready
A11: ="TC-" & TEXT(ROW()-6,"000") -> TC-005 | D11: Kiểm tra giá trị default | F11: 1. Kiểm tra các giá trị default | H11: 1. Các text box đều hiển thị trắng | I11: Pass | J11: Trần Thị Phương Thảo | K11: P2 | L11: Ready
A12: ="TC-" & TEXT(ROW()-6,"000") -> TC-006 | B12: Check Validation | C12: Username | D12: Kiểm tra không nhập Username | E12: Người dùng đang ở màn hình Đăng ký | F12: 1. Nhập thông tin: - Username: bỏ trống - Nhập giá trị hợp lệ cho các trường thông tin còn lại 2. Click button Đăng ký | H12: 2. Hệ thống hiển thị thông báo lỗi: "Please fill out this field" | I12: Pass | J12: Trần Thị Phương Thảo | K12: P1 | L12: Ready
A13: ="TC-" & TEXT(ROW()-6,"000") -> TC-007 | C13: Fullname | D13: Kiểm tra không nhập Fullname | F13: 1. Nhập thông tin: - Fullname: bỏ trống - Nhập giá trị hợp lệ cho các trường thông tin còn lại 2. Click button Đăng ký | H13: 2. Hệ thống hiển thị thông báo lỗi: "Please fill out this field" | I13: Pass | J13: Trần Thị Phương Thảo | K13: P1 | L13: Ready
A14: ="TC-" & TEXT(ROW()-6,"000") -> TC-008 | C14: Address | D14: Kiểm tra không nhập Address | F14: 1. Nhập thông tin: - Address: bỏ trống - Nhập giá trị hợp lệ cho các trường thông tin còn lại 2. Click button Đăng ký | H14: 2. Hệ thống hiển thị thông báo lỗi: "Please fill out this field" | I14: Pass | J14: Trần Thị Phương Thảo | K14: P1 | L14: Ready
A15: ="TC-" & TEXT(ROW()-6,"000") -> TC-009 | C15: Phone | D15: Kiểm tra nhập phone sai định dạng | F15: 1. Nhập thông tin: - Phone: abc123 - Nhập giá trị hợp lệ cho các trường thông tin còn lại 2. Click button Đăng ký | G15: Phone: abc123 | H15: 2. Hệ thống hiển thị thông báo lỗi: "Please match the requested format." | I15: Pass | J15: Trần Thị Phương Thảo | K15: P1 | L15: Ready
A16: ="TC-" & TEXT(ROW()-6,"000") -> TC-010 | D16: Kiểm tra nhập phone chứa ký tự đặc biệt | F16: 1. Nhập thông tin: - Phone: 0946680756@ - Nhập giá trị hợp lệ cho các trường thông tin còn lại 2. Click button Đăng ký | H16: 2. Hệ thống hiển thị thông báo lỗi: "Please match the requested format." | I16: Pass | J16: Trần Thị Phương Thảo | K16: P1 | L16: Ready
A17: ="TC-" & TEXT(ROW()-6,"000") -> TC-011 | D17: Kiểm tra không nhập số phone | F17: 1. Nhập thông tin: - Phone: bỏ trống - Nhập giá trị hợp lệ cho các trường thông tin còn lại 2. Click button Đăng ký | H17: 2. Hệ thống hiển thị thông báo lỗi: "Please fill out this field" | I17: Pass | J17: Trần Thị Phương Thảo | K17: P1 | L17: Ready
A18: ="TC-" & TEXT(ROW()-6,"000") -> TC-012 | D18: Kiểm tra nhập số phone >10 số | F18: 1. Nhập thông tin: - Phone: 09466807567 - Nhập giá trị hợp lệ cho các trường thông tin còn lại 2. Click button Đăng ký | G18: Phone: 09466807567 | H18: 2. Hệ thống hiển thị thông báo lỗi: "Please match the requested format." | I18: Pass | J18: Trần Thị Phương Thảo | K18: P1 | L18: Ready
A19: ="TC-" & TEXT(ROW()-6,"000") -> TC-013 | D19: Kiểm tra nhập số phone < 10 số | F19: 1. Nhập thông tin: - Phone: 094668 - Nhập giá trị hợp lệ cho các trường thông tin còn lại 2. Click button Đăng ký | G19: Phone: 094668 | H19: 2. Hệ thống hiển thị thông báo lỗi: "Please match the requested format." | I19: Pass | J19: Trần Thị Phương Thảo | K19: P1 | L19: Ready
A20: ="TC-" & TEXT(ROW()-6,"000") -> TC-014 | C20: Email | D20: Không nhập email | E20: Người dùng đang ở màn hình Đăng ký | F20: 1. Nhập thông tin: - Email: bỏ trống - Nhập giá trị hợp lệ cho các trường thông tin còn lại 2. Click button Đăng ký | H20: 2. Hệ thống hiển thị thông báo lỗi: "Please fill out this field" | I20: Pass | J20: Trần Thị Phương Thảo | K20: P1 | L20: Ready
A21: ="TC-" & TEXT(ROW()-6,"000") -> TC-015 | D21: Kiểm tra nhập email sai định dạng | F21: 1. Nhập thông tin: - Email: thaogmail.com - Nhập giá trị hợp lệ cho các trường thông tin còn lại 2. Click button Đăng ký | G21: Email: thaogmail.com | H21: 2. Hệ thống hiển thị thông báo lỗi: “Please include an ‘@’ in the email address. ‘phuongthao270204.com’ is missing an ‘@’” | I21: Pass | J21: Trần Thị Phương Thảo | K21: P1 | L21: Ready
A22: ="TC-" & TEXT(ROW()-6,"000") -> TC-016 | C22: Password | D22: Kiểm tra nhập khẩu không khớp | F22: 1. Nhập thông tin: - Nhập Password: thao123 - Nhập Re-Enter Password: thao456 - Nhập giá trị hợp lệ cho các trường thông tin còn lại 2. Click button Đăng ký | G22: - Password: thao123 - Re-Enter Password: thao456 | H22: 2. Hệ thống hiển thị lỗi trang | I22: Pass | J22: Trần Thị Phương Thảo | K22: P1 | L22: Ready
A23: ="TC-" & TEXT(ROW()-6,"000") -> TC-017 | D23: Kiểm tra không nhập mật khẩu | F23: 1. Nhập thông tin: - Password: bỏ trống - Nhập giá trị hợp lệ cho các trường thông tin còn lại 2. Click button Đăng ký | H23: 2. Hệ thống hiển thị thông báo lỗi: "Please fill out this field" | I23: Pass | J23: Trần Thị Phương Thảo | K23: P1 | L23: Ready
A24: ="TC-" & TEXT(ROW()-6,"000") -> TC-018 | C24: Enter the password | D24: Kiểm tra không nhập nhắc lại mật khẩu | F24: 1. Nhập thông tin: - Enter the password: bỏ trống - Nhập giá trị hợp lệ cho các trường thông tin còn lại 2. Click button Đăng ký | H24: 2. Hệ thống hiển thị thông báo lỗi: "Please fill out this field" | I24: Pass | J24: Trần Thị Phương Thảo | K24: P1 | L24: Ready
A25: ="TC-" & TEXT(ROW()-6,"000") -> TC-019 | B25: Check business | C25: Kiểm tra button Đăng ký | D25: Kiểm tra người dùng đăng ký thành công với các thông tin hợp lệ | E25: Người dùng đang ở màn hình Đăng ký và chưa có tài khoản | F25: 1. Nhập thông tin: - Nhập giá trị hợp lệ cho các trường thông tin còn lại 2. Click button Đăng ký | G25: Username: thaoo Fullname: Phuongthao Email: phuongthao270204@gmail Phone: 0946680756 Address: 25 Đường Cầu Diễn Password: 123456 Re-Enter Password: 123456 | H25: 2. Hệ thống đăng ký tài khoản thành công và thông tin được lưu trong bảng tài khoản | I25: Pass | J25: Trần Thị Phương Thảo | K25: P1 | L25: Ready
A26: ="TC-" & TEXT(ROW()-6,"000") -> TC-020 | D26: Kiểm tra người dùng đăng ký tài khoản với email đã tồn tại | E26: Người dùng đang ở màn hình Đăng ký và email đã tồn tại | F26: 1. Nhập thông tin: - Email: phuongthao270204@gmail.com - Nhập giá trị hợp lệ cho các trường thông tin còn lại 2. Click button Đăng ký | H26: 2. Hệ thống hiển thị thông báo lỗi: "Email đã tồn tại” | I26: Fail | J26: Trần Thị Phương Thảo | K26: P1 | L26: Ready

Sheet Đăng nhập
A1: Module Code | B1: Đăng nhập
A2: Test requirement | B2: <Brief description about requirements which are tested in this sheet>
A3: Tester
A4: Pass | B4: Fail | C4: Untested | D4: N/A | E4: Number of Test cases
A5: =COUNTIF(I6:I996,"Pass") -> 10 | B5: =COUNTIF(I6:I996,"Fail") -> 0 | C5: =E5-D5-A5-B5 -> 1 | D5: =COUNTIF(H$6:I$997,"N/A") -> 0 | E5: =COUNTA(A6:A1000) -> 11
A6: Test Case ID | B6: Group Name | C6: Sub Group Name | D6: Test Case Description | E6: Precondition | F6: Test Case Procedure | G6: Test data | H6: Expected Output | I6: Result | J6: Tester | K6: Priority | L6: Status
A7: ="TC-" & TEXT(ROW()-ROW($A$7)+1 + COUNTIF('Đăng ký'!A:A,"TC-*"),"000") -> TC-021 | B7: Access right | D7: Kiểm tra cách vào màn hình đăng nhập | E7: Người dùng chưa đăng nhập | F7: 1. Truy cập website 2. Click “Đăng nhập” | H7: 1. Hiển thị màn hình Đăng nhập | I7: Pass | J7: Trần Thị Phương Thảo | K7: P1 | L7: Ready
A8: ="TC-" & TEXT(ROW()-ROW($A$7)+1 + COUNTIF('Đăng ký'!A:A,"TC-*"),"000") -> TC-022 | B8: UI | D8: Kiểm tra số lượng các item | F8: 1. Kiểm tra số lượng các item | H8: 1. Hiển thị đúng số lượng các item trên màn hình | I8: Pass | J8: Trần Thị Phương Thảo | K8: P2 | L8: Ready
A9: ="TC-" & TEXT(ROW()-ROW($A$7)+1 + COUNTIF('Đăng ký'!A:A,"TC-*"),"000") -> TC-023 | D9: Kiểm tra vị trí, font chữ, size chữ, màu sắc | F9: 1. Kiểm tra vị trí, font chữ, size chữ, màu sắc | H9: 1. Hiển thị đúng theo design | I9: Pass | J9: Trần Thị Phương Thảo | K9: P2 | L9: Ready
A10: ="TC-" & TEXT(ROW()-ROW($A$7)+1 + COUNTIF('Đăng ký'!A:A,"TC-*"),"000") -> TC-024 | D10: Kiểm tra trạng thái | F10: 1. Kiểm tra trạng thái các item | H10: 1. Các item đều ở trạng thái enable | I10: Pass | J10: Trần Thị Phương Thảo | K10: P2 | L10: Ready
A11: ="TC-" & TEXT(ROW()-ROW($A$7)+1 + COUNTIF('Đăng ký'!A:A,"TC-*"),"000") -> TC-025 | D11: Kiểm tra giá trị default | F11: 1. Kiểm tra các giá trị default | H11: 1. Các text box đều hiển thị trắng | I11: Pass | J11: Trần Thị Phương Thảo | K11: P2 | L11: Ready
A12: ="TC-" & TEXT(ROW()-ROW($A$7)+1 + COUNTIF('Đăng ký'!A:A,"TC-*"),"000") -> TC-026 | B12: Check Validation | C12: Username | D12: Kiểm tra không nhập tên đăng nhập | E12: Người dùng đang ở màn hình Đăng nhập | F12: 1. Nhập thông tin: - Username: bỏ trống - Nhập giá trị hợp lệ cho các trường thông tin còn lại 2. Click button Login | H12: 2. Hệ thống hiển thị thông báo lỗi yêu cầu nhập tên đăng nhập | I12: Pass | J12: Trần Thị Phương Thảo | K12: P1 | L12: Ready
A13: ="TC-" & TEXT(ROW()-ROW($A$7)+1 + COUNTIF('Đăng ký'!A:A,"TC-*"),"000") -> TC-027 | C13: Password | D13: Kiểm tra không nhập mật khẩu | E13: Người dùng đang ở màn hình Đăng nhập | F13: 1. Nhập thông tin: - Password: bỏ trống - Nhập giá trị hợp lệ cho các trường thông tin còn lại 2. Click button Login | H13: 2. Hệ thống hiển thị thông báo lỗi yêu cầu nhập mật khẩu | I13: Pass | J13: Trần Thị Phương Thảo | K13: P1 | L13: Ready
A14: ="TC-" & TEXT(ROW()-ROW($A$7)+1 + COUNTIF('Đăng ký'!A:A,"TC-*"),"000") -> TC-028 | B14: Check business | C14: Kiểm tra button Login | D14: Kiểm tra người dùng đăng nhập thành công với các thông tin hợp lệ | E14: Người dùng đang ở màn hình Đăng nhập, tài khoản đã tồn tại | F14: 1. Nhập thông tin: - Nhập giá trị hợp lệ cho các trường thông tin còn lại 2. Click button Login | H14: 2. Hệ thống đăng nhập tài khoản thành công và chuyển sang trang chủ | I14: Pass | J14: Trần Thị Phương Thảo | K14: P1 | L14: Ready
A15: ="TC-" & TEXT(ROW()-ROW($A$7)+1 + COUNTIF('Đăng ký'!A:A,"TC-*"),"000") -> TC-029 | D15: Kiểm tra người dùng đăng nhập không thành công vào hệ thống với tên đăng nhập không tồn tại trong hệ thống | E15: Người dùng đang ở màn hình Đăng nhập, tài khoản không tồn tại | F15: 1. Nhập thông tin: - Tên đăng nhập: thao - Nhập giá trị hợp lệ cho các trường thông tin còn lại 2. Click button Login | G15: Username: thao | H15: 2. Hệ thống hiển thị thông báo lỗi: “Username Incorrect” | I15: Pass | J15: Trần Thị Phương Thảo | K15: P1 | L15: Ready
A16: ="TC-" & TEXT(ROW()-ROW($A$7)+1 + COUNTIF('Đăng ký'!A:A,"TC-*"),"000") -> TC-030 | D16: Kiểm tra người dùng đăng nhập không thành công vào hệ thống khi nhập sai mật khẩu | E16: Người dùng đang ở màn hình Đăng nhập, tài khoản đã tồn tại | F16: 1. Nhập thông tin: - Password: 12345 - Nhập giá trị hợp lệ cho các trường thông tin còn lại 2. Click button Login | G16: Password: 12345/123456 | H16: 2. Hệ thống hiển thị thông báo lỗi: "Password không đúng" | I16: Pass | J16: Trần Thị Phương Thảo | K16: P1 | L16: Ready

Sheet Tìm kiếm bài viết
A1: Module Code | B1: Tìm kiếm bài viết
A2: Test requirement | B2: <Brief description about requirements which are tested in this sheet>
A3: Tester
A4: Pass | B4: Fail | C4: Untested | D4: N/A | E4: Number of Test cases
A5: =COUNTIF(I6:I994,"Pass") -> 10 | B5: =COUNTIF(I6:I994,"Fail") -> 0 | C5: =E5-D5-A5-B5 -> 1 | D5: =COUNTIF(H$6:I$995,"N/A") -> 0 | E5: =COUNTA(A6:A998) -> 11
A6: Test Case ID | B6: Group Name | C6: Sub Group Name | D6: Test Case Description | E6: Precondition | F6: Test Case Procedure | G6: Test data | H6: Expected Output | I6: Result | J6: Tester | K6: Priority | L6: Status
A7: ="TC-" & TEXT( ROW()-ROW($A$7)+1 + COUNTIF('Đăng ký'!A:A,"TC-*") + COUNTIF('Đăng nhập'!A:A,"TC-*"),"000") -> TC-031 | B7: Access right | D7: Kiểm tra truy cập trang Tin tức | E7: Người dùng truy cập website | F7: 1. Truy cập website 2. Click menu “Tin tức” | H7: 1. Hiển thị màn hình trang Tin tức | I7: Pass | J7: Trần Thị Phương Thảo | K7: P1 | L7: Ready
A8: ="TC-" & TEXT( ROW()-ROW($A$7)+1 + COUNTIF('Đăng ký'!A:A,"TC-*") + COUNTIF('Đăng nhập'!A:A,"TC-*"),"000") -> TC-032 | B8: UI | D8: Kiểm tra số lượng các item | F8: 1. Kiểm tra số lượng các item | H8: 1. Hiển thị đúng số lượng các item trên màn hình | I8: Pass | J8: Trần Thị Phương Thảo | K8: P2 | L8: Ready
A9: ="TC-" & TEXT( ROW()-ROW($A$7)+1 + COUNTIF('Đăng ký'!A:A,"TC-*") + COUNTIF('Đăng nhập'!A:A,"TC-*"),"000") -> TC-033 | D9: Kiểm tra vị trí, font chữ, size chữ, màu sắc | F9: 1. Kiểm tra vị trí, font chữ, size chữ, màu sắc | H9: 1. Hiển thị đúng theo design | I9: Pass | J9: Trần Thị Phương Thảo | K9: P2 | L9: Ready
A10: ="TC-" & TEXT( ROW()-ROW($A$7)+1 + COUNTIF('Đăng ký'!A:A,"TC-*") + COUNTIF('Đăng nhập'!A:A,"TC-*"),"000") -> TC-034 | D10: Kiểm tra trạng thái | F10: 1. Kiểm tra trạng thái các item | H10: 1. Các item đều ở trạng thái enable | I10: Pass | J10: Trần Thị Phương Thảo | K10: P2 | L10: Ready
A11: ="TC-" & TEXT( ROW()-ROW($A$7)+1 + COUNTIF('Đăng ký'!A:A,"TC-*") + COUNTIF('Đăng nhập'!A:A,"TC-*"),"000") -> TC-035 | D11: Kiểm tra giá trị default | F11: 1. Kiểm tra các giá trị default | H11: 1. Các text box đều hiển thị trắng | I11: Pass | J11: Trần Thị Phương Thảo | K11: P2 | L11: Ready
A12: ="TC-" & TEXT( ROW()-ROW($A$7)+1 + COUNTIF('Đăng ký'!A:A,"TC-*") + COUNTIF('Đăng nhập'!A:A,"TC-*"),"000") -> TC-036 | B12: Check Validation | C12: Kiểm tra keyword | D12: Kiểm tra không nhập từ khóa | E12: Người dùng truy cập website | F12: 1. Nhập thông tin: - Để trống ô tìm kiếm 2. Click “Search” | H12: 2. Hệ thống hiển thị danh sách tất cả các bài viết | I12: Pass | J12: Trần Thị Phương Thảo | K12: P1 | L12: Ready
A13: ="TC-" & TEXT( ROW()-ROW($A$7)+1 + COUNTIF('Đăng ký'!A:A,"TC-*") + COUNTIF('Đăng nhập'!A:A,"TC-*"),"000") -> TC-037 | D13: Kiểm tra tìm kiếm không phân biệt hoa thường | E13: Người dùng truy cập website và có dữ liệu bài viết trong hệ thống | F13: 1. Nhập thông tin: - Nhập từ khóa: TÀU 2. Click “Search” | G13: CHUYẾN TÀU | H13: 2. Hệ thống trả về kết quả chứa từ khóa không phân biệt hoa thường | I13: Pass
A14: ="TC-" & TEXT( ROW()-ROW($A$7)+1 + COUNTIF('Đăng ký'!A:A,"TC-*") + COUNTIF('Đăng nhập'!A:A,"TC-*"),"000") -> TC-038 | B14: Check business | D14: Kiểm tra người dùng tìm kiếm với từ khóa hợp lệ | E14: Người dùng truy cập website và có dữ liệu bài viết trong hệ thống | F14: 1. Nhập thông tin: - Nhập từ khóa: chuyến tàu 2. Click “Search” | G14: chuyến tàu | H14: 2. Hệ thống hiển thị danh sách bài viết chứa từ khóa | I14: Pass | J14: Trần Thị Phương Thảo | K14: P1 | L14: Ready
A15: ="TC-" & TEXT( ROW()-ROW($A$7)+1 + COUNTIF('Đăng ký'!A:A,"TC-*") + COUNTIF('Đăng nhập'!A:A,"TC-*"),"000") -> TC-039 | D15: Kiểm tra người dùng tìm kiếm từ khóa không trả về kết quả hợp lệ | E15: Người dùng truy cập website và không có dữ liệu bài viết trong hệ thống | F15: 1. Nhập thông tin: - Nhập từ khóa: xyz123 2. Click “Search” | G15: xyz123 | H15: 2. Hệ thống không hiển thị bài viết nào liên quan đến từ khóa | I15: Pass | J15: Trần Thị Phương Thảo | K15: P1 | L15: Ready
A16: ="TC-" & TEXT( ROW()-ROW($A$7)+1 + COUNTIF('Đăng ký'!A:A,"TC-*") + COUNTIF('Đăng nhập'!A:A,"TC-*"),"000") -> TC-040 | D16: Kiểm tra tìm kiếm nhiều từ khóa một lúc | E16: Người dùng truy cập website và có dữ liệu bài viết trong hệ thống | F16: 1. Nhập thông tin: - Nhập từ khóa: Hành trình lan tỏa giá trị nhân văn và quảng bá du lịch Việt Nam 2. Click “Search” | G16: Hành trình lan tỏa giá trị nhân văn và quảng bá du lịch Việt Nam | H16: 2. Hệ thống hiển thị danh sách bài viết chứa từ khóa | I16: Pass | J16: Trần Thị Phương Thảo | K16: P2 | L16: Ready

Sheet Xem chủ đề bài viết
A1: Module Code | B1: Xem chủ đề bài viết
A2: Test requirement | B2: <Brief description about requirements which are tested in this sheet>
A3: Tester
A4: Pass | B4: Fail | C4: Untested | D4: N/A | E4: Number of Test cases
A5: =COUNTIF(I6:I995,"Pass") -> 8 | B5: =COUNTIF(I6:I995,"Fail") -> 0 | C5: =E5-D5-A5-B5 -> 1 | D5: =COUNTIF(H$6:I$996,"N/A") -> 0 | E5: =COUNTA(A6:A999) -> 9
A6: Test Case ID | B6: Group Name | C6: Sub Group Name | D6: Test Case Description | E6: Precondition | F6: Test Case Procedure | G6: Test data | H6: Expected Output | I6: Result | J6: Tester | K6: Priority | L6: Status
A7: ="TC-" & TEXT( ROW()-ROW($A$7)+1 + COUNTIF('Đăng ký'!A:A,"TC-*") + COUNTIF('Đăng nhập'!A:A,"TC-*") + COUNTIF('Tìm kiếm bài viết'!A:A,"TC-*"),"000") -> TC-041 | B7: Access right | D7: Kiểm tra truy cập trang Tin tức | E7: Người dùng truy cập website | F7: 1. Truy cập website 2. Click menu “Tin tức” | H7: 1. Hiển thị màn hình trang Tin tức | I7: Pass | J7: Trần Thị Phương Thảo | K7: P1 | L7: Ready
A8: ="TC-" & TEXT( ROW()-ROW($A$7)+1 + COUNTIF('Đăng ký'!A:A,"TC-*") + COUNTIF('Đăng nhập'!A:A,"TC-*") + COUNTIF('Tìm kiếm bài viết'!A:A,"TC-*"),"000") -> TC-042 | B8: UI | D8: Kiểm tra số lượng các item | E8: Người dùng đang ở trang Tin tức | F8: 1. Kiểm tra số lượng các item | H8: 1. Hiển thị đúng số lượng các item trên màn hình | I8: Pass | J8: Trần Thị Phương Thảo | K8: P2 | L8: Ready
A9: ="TC-" & TEXT( ROW()-ROW($A$7)+1 + COUNTIF('Đăng ký'!A:A,"TC-*") + COUNTIF('Đăng nhập'!A:A,"TC-*") + COUNTIF('Tìm kiếm bài viết'!A:A,"TC-*"),"000") -> TC-043 | D9: Kiểm tra vị trí, font chữ, size chữ, màu sắc | F9: 1. Kiểm tra vị trí, font chữ, size chữ, màu sắc | H9: 1. Hiển thị đúng theo design | I9: Pass | J9: Trần Thị Phương Thảo | K9: P2 | L9: Ready
A10: ="TC-" & TEXT( ROW()-ROW($A$7)+1 + COUNTIF('Đăng ký'!A:A,"TC-*") + COUNTIF('Đăng nhập'!A:A,"TC-*") + COUNTIF('Tìm kiếm bài viết'!A:A,"TC-*"),"000") -> TC-044 | D10: Kiểm tra trạng thái | F10: 1. Kiểm tra trạng thái các item | H10: 1. Các item đều ở trạng thái enable | I10: Pass | J10: Trần Thị Phương Thảo | K10: P2 | L10: Ready
A11: ="TC-" & TEXT( ROW()-ROW($A$7)+1 + COUNTIF('Đăng ký'!A:A,"TC-*") + COUNTIF('Đăng nhập'!A:A,"TC-*") + COUNTIF('Tìm kiếm bài viết'!A:A,"TC-*"),"000") -> TC-045 | D11: Kiểm tra giá trị default | F11: 1. Kiểm tra các giá trị default | H11: 1. Các text box đều hiển thị trắng | I11: Pass | J11: Trần Thị Phương Thảo | K11: P2 | L11: Ready
A12: ="TC-" & TEXT( ROW()-ROW($A$7)+1 + COUNTIF('Đăng ký'!A:A,"TC-*") + COUNTIF('Đăng nhập'!A:A,"TC-*") + COUNTIF('Tìm kiếm bài viết'!A:A,"TC-*"),"000") -> TC-046 | B12: Check business | D12: Kiểm tra hiển thị bài viết theo chủ đề | E12: Người dùng đã chọn chủ đề | F12: 1. Click chủ đề “Vé tàu nội địa” | G12: Vé tàu nội địa | H12: 2. Hiển thị danh sách bài viết thuộc chủ đề | I12: Pass | J12: Trần Thị Phương Thảo | K12: P1 | L12: Ready
A13: ="TC-" & TEXT( ROW()-ROW($A$7)+1 + COUNTIF('Đăng ký'!A:A,"TC-*") + COUNTIF('Đăng nhập'!A:A,"TC-*") + COUNTIF('Tìm kiếm bài viết'!A:A,"TC-*"),"000") -> TC-047 | D13: Kiểm tra bài viết khi không có dữ liệu | E13: Chủ đề không có bài viết | F13: 1. Click chủ đề không có bài | H13: 2. Hệ thống không hiển thị danh sách bài viết theo chủ đề được chọn | I13: Pass | J13: Trần Thị Phương Thảo | K13: P2 | L13: Ready
A14: ="TC-" & TEXT( ROW()-ROW($A$7)+1 + COUNTIF('Đăng ký'!A:A,"TC-*") + COUNTIF('Đăng nhập'!A:A,"TC-*") + COUNTIF('Tìm kiếm bài viết'!A:A,"TC-*"),"000") -> TC-048 | D14: Kiểm tra click vào bài viết | E14: Người dùng đang xem danh sách bài | F14: 1. Click 1 bài viết | H14: 2. Hiển thị chi tiết bài viết | I14: Pass | J14: Trần Thị Phương Thảo | K14: P1 | L14: Ready

Sheet Xem chi tiết bài viết
A1: Module Code | B1: Xem chi tiết bài viết
A2: Test requirement | B2: <Brief description about requirements which are tested in this sheet>
A3: Tester
A4: Pass | B4: Fail | C4: Untested | D4: N/A | E4: Number of Test cases
A5: =COUNTIF(I6:I995,"Pass") -> 8 | B5: =COUNTIF(I6:I995,"Fail") -> 0 | C5: =E5-D5-A5-B5 -> 3 | D5: =COUNTIF(H$6:I$996,"N/A") -> 0 | E5: =COUNTA(A6:A999) -> 11
A6: Test Case ID | B6: Group Name | C6: Sub Group Name | D6: Test Case Description | E6: Precondition | F6: Test Case Procedure | G6: Test data | H6: Expected Output | I6: Result | J6: Tester | K6: Priority | L6: Status
A7: ="TC-" & TEXT( ROW()-ROW($A$7)+1 + COUNTIF('Đăng ký'!A:A,"TC-*") + COUNTIF('Đăng nhập'!A:A,"TC-*") + COUNTIF('Tìm kiếm bài viết'!A:A,"TC-*") + COUNTIF('Xem chủ đề bài viết'!A:A,"TC-*"),"000") -> TC-049 | B7: Access right | D7: Kiểm tra truy cập màn hình chi tiết bài viết | E7: Người dùng đang ở trang danh sách bài viết | F7: 1. Click vào 1 bài viết bất kỳ | H7: 1. Hiển thị màn hình chi tiết bài viết | I7: Pass | J7: Trần Thị Phương Thảo | K7: P1 | L7: Ready
A8: ="TC-" & TEXT( ROW()-ROW($A$7)+1 + COUNTIF('Đăng ký'!A:A,"TC-*") + COUNTIF('Đăng nhập'!A:A,"TC-*") + COUNTIF('Tìm kiếm bài viết'!A:A,"TC-*") + COUNTIF('Xem chủ đề bài viết'!A:A,"TC-*"),"000") -> TC-050 | B8: UI | D8: Kiểm tra hiển thị tiêu đề bài viết | E8: Người dùng đang ở màn hình chi tiết | F8: 1. Quan sát tiêu đề | H8: 1. Hiển thị đúng tiêu đề bài viết | I8: Pass | J8: Trần Thị Phương Thảo | K8: P1 | L8: Ready
A9: ="TC-" & TEXT( ROW()-ROW($A$7)+1 + COUNTIF('Đăng ký'!A:A,"TC-*") + COUNTIF('Đăng nhập'!A:A,"TC-*") + COUNTIF('Tìm kiếm bài viết'!A:A,"TC-*") + COUNTIF('Xem chủ đề bài viết'!A:A,"TC-*"),"000") -> TC-051 | D9: Kiểm tra hiển thị hình ảnh | F9: 1. Quan sát hình ảnh | H9: 1. Hiển thị đúng hình ảnh bài viết | I9: Pass | J9: Trần Thị Phương Thảo | K9: P2 | L9: Ready
A10: ="TC-" & TEXT( ROW()-ROW($A$7)+1 + COUNTIF('Đăng ký'!A:A,"TC-*") + COUNTIF('Đăng nhập'!A:A,"TC-*") + COUNTIF('Tìm kiếm bài viết'!A:A,"TC-*") + COUNTIF('Xem chủ đề bài viết'!A:A,"TC-*"),"000") -> TC-052 | D10: Kiểm tra hiển thị nội dung bài viết | F10: 1. Quan sát nội dung | H10: 1. Hiển thị đầy đủ nội dung bài viết | I10: Pass | J10: Trần Thị Phương Thảo | K10: P1 | L10: Ready
A11: ="TC-" & TEXT( ROW()-ROW($A$7)+1 + COUNTIF('Đăng ký'!A:A,"TC-*") + COUNTIF('Đăng nhập'!A:A,"TC-*") + COUNTIF('Tìm kiếm bài viết'!A:A,"TC-*") + COUNTIF('Xem chủ đề bài viết'!A:A,"TC-*"),"000") -> TC-053 | D11: Kiểm tra bố cục hiển thị | F11: 1. Kiểm tra layout (title, image, content) | H11: 1. Hiển thị đúng theo design | I11: Pass | J11: Trần Thị Phương Thảo | K11: P2 | L11: Ready
A12: ="TC-" & TEXT( ROW()-ROW($A$7)+1 + COUNTIF('Đăng ký'!A:A,"TC-*") + COUNTIF('Đăng nhập'!A:A,"TC-*") + COUNTIF('Tìm kiếm bài viết'!A:A,"TC-*") + COUNTIF('Xem chủ đề bài viết'!A:A,"TC-*"),"000") -> TC-054 | B12: Check business | D12: Kiểm tra load dữ liệu bài viết từ database | E12: Có dữ liệu bài viết | F12: 1. Click bài viết | H12: 2. Dữ liệu hiển thị đúng từ BAI_VIET | I12: Pass | J12: Trần Thị Phương Thảo | K12: P1 | L12: Ready
A13: ="TC-" & TEXT( ROW()-ROW($A$7)+1 + COUNTIF('Đăng ký'!A:A,"TC-*") + COUNTIF('Đăng nhập'!A:A,"TC-*") + COUNTIF('Tìm kiếm bài viết'!A:A,"TC-*") + COUNTIF('Xem chủ đề bài viết'!A:A,"TC-*"),"000") -> TC-055 | D13: Kiểm tra tính chính xác dữ liệu | E13: Có dữ liệu | F13: 1. So sánh UI với database | H13: 2. Hệ thống hiển thị nội dung đúng với database | I13: Pass | J13: Trần Thị Phương Thảo | K13: P1 | L13: Ready
A14: ="TC-" & TEXT( ROW()-ROW($A$7)+1 + COUNTIF('Đăng ký'!A:A,"TC-*") + COUNTIF('Đăng nhập'!A:A,"TC-*") + COUNTIF('Tìm kiếm bài viết'!A:A,"TC-*") + COUNTIF('Xem chủ đề bài viết'!A:A,"TC-*"),"000") -> TC-056 | D14: Kiểm tra trạng thái bài viết | E14: Có bài viết ẩn | F14: 1. Truy cập bài viết trạng thái ẩn | H14: 2. Hệ thống không hiển thị bài viết | I14: Pass | J14: Trần Thị Phương Thảo | K14: P1 | L14: Ready
A15: ="TC-" & TEXT( ROW()-ROW($A$7)+1 + COUNTIF('Đăng ký'!A:A,"TC-*") + COUNTIF('Đăng nhập'!A:A,"TC-*") + COUNTIF('Tìm kiếm bài viết'!A:A,"TC-*") + COUNTIF('Xem chủ đề bài viết'!A:A,"TC-*"),"000") -> TC-057
A16: ="TC-" & TEXT( ROW()-ROW($A$7)+1 + COUNTIF('Đăng ký'!A:A,"TC-*") + COUNTIF('Đăng nhập'!A:A,"TC-*") + COUNTIF('Tìm kiếm bài viết'!A:A,"TC-*") + COUNTIF('Xem chủ đề bài viết'!A:A,"TC-*"),"000") -> TC-058

Sheet Tìm kiếm chuyến đi
A1: Module Code | B1: Tìm kiếm chuyến đi
A2: Test requirement | B2: <Brief description about requirements which are tested in this sheet>
A3: Tester
A4: Pass | B4: Fail | C4: Untested | D4: N/A | E4: Number of Test cases
A5: =COUNTIF(I6:I993,"Pass") -> 14 | B5: =COUNTIF(I6:I993,"Fail") -> 0 | C5: =E5-D5-A5-B5 -> 1 | D5: =COUNTIF(H$6:I$994,"N/A") -> 0 | E5: =COUNTA(A6:A997) -> 15
A6: Test Case ID | B6: Group Name | C6: Sub Group Name | D6: Test Case Description | E6: Precondition | F6: Test Case Procedure | G6: Test data | H6: Expected Output | I6: Result | J6: Tester | K6: Priority | L6: Status
A7: ="TC-" & TEXT( ROW()-ROW($A$7)+1 + COUNTIF('Đăng ký'!A:A,"TC-*") + COUNTIF('Đăng nhập'!A:A,"TC-*") + COUNTIF('Tìm kiếm bài viết'!A:A,"TC-*") + COUNTIF('Xem chủ đề bài viết'!A:A,"TC-*") + COUNTIF('Xem chi tiết bài viết'!A:A,"TC-*"),"000") -> TC-059 | B7: Access right | D7: Kiểm tra truy cập chức năng tìm kiếm | E7: Người dùng đã vào website | F7: 1. Click vào Trang chủ 2. Quan sát form tìm kiếm | H7: 1. Hiển thị form tìm kiếm chuyến đi | I7: Pass | J7: Trần Thị Phương Thảo | K7: P1 | L7: Ready
A8: ="TC-" & TEXT( ROW()-ROW($A$7)+1 + COUNTIF('Đăng ký'!A:A,"TC-*") + COUNTIF('Đăng nhập'!A:A,"TC-*") + COUNTIF('Tìm kiếm bài viết'!A:A,"TC-*") + COUNTIF('Xem chủ đề bài viết'!A:A,"TC-*") + COUNTIF('Xem chi tiết bài viết'!A:A,"TC-*"),"000") -> TC-060 | B8: UI | D8: Kiểm tra số lượng các item | F8: 1. Kiểm tra số lượng các item | H8: 1. Hiển thị đúng số lượng các item trên màn hình | I8: Pass | J8: Trần Thị Phương Thảo | K8: P1 | L8: Ready
A9: ="TC-" & TEXT( ROW()-ROW($A$7)+1 + COUNTIF('Đăng ký'!A:A,"TC-*") + COUNTIF('Đăng nhập'!A:A,"TC-*") + COUNTIF('Tìm kiếm bài viết'!A:A,"TC-*") + COUNTIF('Xem chủ đề bài viết'!A:A,"TC-*") + COUNTIF('Xem chi tiết bài viết'!A:A,"TC-*"),"000") -> TC-061 | D9: Kiểm tra vị trí, font chữ, size chữ, màu sắc | F9: 1. Kiểm tra vị trí, font chữ, size chữ, màu sắc | H9: 1. Hiển thị đúng theo design | I9: Pass | J9: Trần Thị Phương Thảo | K9: P2 | L9: Ready
A10: ="TC-" & TEXT( ROW()-ROW($A$7)+1 + COUNTIF('Đăng ký'!A:A,"TC-*") + COUNTIF('Đăng nhập'!A:A,"TC-*") + COUNTIF('Tìm kiếm bài viết'!A:A,"TC-*") + COUNTIF('Xem chủ đề bài viết'!A:A,"TC-*") + COUNTIF('Xem chi tiết bài viết'!A:A,"TC-*"),"000") -> TC-062 | D10: Kiểm tra danh sách Ga đi | E10: Người dùng click dropdown | F10: 1. Click chọn Ga đi | H10: 1. Hiển thị danh sách các ga từ database | I10: Pass | J10: Trần Thị Phương Thảo | K10: P2 | L10: Ready
A11: ="TC-" & TEXT( ROW()-ROW($A$7)+1 + COUNTIF('Đăng ký'!A:A,"TC-*") + COUNTIF('Đăng nhập'!A:A,"TC-*") + COUNTIF('Tìm kiếm bài viết'!A:A,"TC-*") + COUNTIF('Xem chủ đề bài viết'!A:A,"TC-*") + COUNTIF('Xem chi tiết bài viết'!A:A,"TC-*"),"000") -> TC-063 | D11: Kiểm tra danh sách Ga đến | F11: 1. Click chọn Ga đến | H11: 1. Hiển thị danh sách các ga từ database | I11: Pass | J11: Trần Thị Phương Thảo | K11: P2 | L11: Ready
A12: ="TC-" & TEXT( ROW()-ROW($A$7)+1 + COUNTIF('Đăng ký'!A:A,"TC-*") + COUNTIF('Đăng nhập'!A:A,"TC-*") + COUNTIF('Tìm kiếm bài viết'!A:A,"TC-*") + COUNTIF('Xem chủ đề bài viết'!A:A,"TC-*") + COUNTIF('Xem chi tiết bài viết'!A:A,"TC-*"),"000") -> TC-064 | D12: Kiểm tra trạng thái | F12: 1. Kiểm tra trạng thái các item | H12: 1. Các item đều ở trạng thái enable | I12: Pass | J12: Trần Thị Phương Thảo | K12: P1 | L12: Ready
A13: ="TC-" & TEXT( ROW()-ROW($A$7)+1 + COUNTIF('Đăng ký'!A:A,"TC-*") + COUNTIF('Đăng nhập'!A:A,"TC-*") + COUNTIF('Tìm kiếm bài viết'!A:A,"TC-*") + COUNTIF('Xem chủ đề bài viết'!A:A,"TC-*") + COUNTIF('Xem chi tiết bài viết'!A:A,"TC-*"),"000") -> TC-065 | D13: Kiểm tra giá trị default | F13: 1. Kiểm tra các giá trị default | H13: 1. Các text box đều hiển thị trắng | I13: Pass | J13: Trần Thị Phương Thảo | K13: P2 | L13: Ready
A14: ="TC-" & TEXT( ROW()-ROW($A$7)+1 + COUNTIF('Đăng ký'!A:A,"TC-*") + COUNTIF('Đăng nhập'!A:A,"TC-*") + COUNTIF('Tìm kiếm bài viết'!A:A,"TC-*") + COUNTIF('Xem chủ đề bài viết'!A:A,"TC-*") + COUNTIF('Xem chi tiết bài viết'!A:A,"TC-*"),"000") -> TC-066 | B14: Check Validation | D14: Kiểm tra bỏ trống tất cả | E14: Người dùng đang ở form tìm kiếm | F14: 1. Click “Tra cứu” khi chưa nhập | H14: 2. Hệ thống hiển thị thông báo lỗi: "Please fill out this field" | I14: Pass | J14: Trần Thị Phương Thảo | K14: P1 | L14: Ready
A15: ="TC-" & TEXT( ROW()-ROW($A$7)+1 + COUNTIF('Đăng ký'!A:A,"TC-*") + COUNTIF('Đăng nhập'!A:A,"TC-*") + COUNTIF('Tìm kiếm bài viết'!A:A,"TC-*") + COUNTIF('Xem chủ đề bài viết'!A:A,"TC-*") + COUNTIF('Xem chi tiết bài viết'!A:A,"TC-*"),"000") -> TC-067 | C15: Ngày đi | D15: Kiểm tra không nhập ngày đi | F15: 1. Nhập thông tin: - Ngày đi: Bỏ trống - Nhập giá trị hợp lệ cho các trường thông tin còn lại 2. Click button Tra cứu | H15: 2. Hệ thống hiển thị thông báo lỗi: "Please fill out this field" | I15: Pass | J15: Trần Thị Phương Thảo | K15: P1 | L15: Ready
A16: ="TC-" & TEXT( ROW()-ROW($A$7)+1 + COUNTIF('Đăng ký'!A:A,"TC-*") + COUNTIF('Đăng nhập'!A:A,"TC-*") + COUNTIF('Tìm kiếm bài viết'!A:A,"TC-*") + COUNTIF('Xem chủ đề bài viết'!A:A,"TC-*") + COUNTIF('Xem chi tiết bài viết'!A:A,"TC-*"),"000") -> TC-068 | D16: Kiểm tra chọn ngày đi trong quá khứ | F16: 1. 1. Nhập thông tin: - Chọn ngày đi < ngày hiện tại 2. Click Tra cứu | G16: 46110 | H16: 2. Hệ thống không cho chọn ngày nhỏ hơn ngày hiện tại | I16: Pass | J16: Trần Thị Phương Thảo | K16: P1 | L16: Ready
A17: ="TC-" & TEXT( ROW()-ROW($A$7)+1 + COUNTIF('Đăng ký'!A:A,"TC-*") + COUNTIF('Đăng nhập'!A:A,"TC-*") + COUNTIF('Tìm kiếm bài viết'!A:A,"TC-*") + COUNTIF('Xem chủ đề bài viết'!A:A,"TC-*") + COUNTIF('Xem chi tiết bài viết'!A:A,"TC-*"),"000") -> TC-069 | C17: Ngày về | D17: Kiểm tra không nhập ngày về | F17: 1. Nhập thông tin: - Ngày đi: Bỏ trống - Nhập giá trị hợp lệ cho các trường thông tin còn lại 2. Click button Tra cứu | I17: Pass | J17: Trần Thị Phương Thảo | K17: P1 | L17: Ready
A18: ="TC-" & TEXT( ROW()-ROW($A$7)+1 + COUNTIF('Đăng ký'!A:A,"TC-*") + COUNTIF('Đăng nhập'!A:A,"TC-*") + COUNTIF('Tìm kiếm bài viết'!A:A,"TC-*") + COUNTIF('Xem chủ đề bài viết'!A:A,"TC-*") + COUNTIF('Xem chi tiết bài viết'!A:A,"TC-*"),"000") -> TC-070 | D18: Kiểm tra chọn ngày nhỏ hơn ngày đi | F18: 1. Nhập thông tin: - Chọn ngày về < ngày đi - Nhập giá trị hợp lệ cho các trường thông tin còn lại 2. Click Tra cứu | H18: 2. Hệ thống hiển thị thông báo: Return date must be greater than or equal to departure date! | I18: Pass | J18: Trần Thị Phương Thảo | K18: P1 | L18: Ready
A19: ="TC-" & TEXT( ROW()-ROW($A$7)+1 + COUNTIF('Đăng ký'!A:A,"TC-*") + COUNTIF('Đăng nhập'!A:A,"TC-*") + COUNTIF('Tìm kiếm bài viết'!A:A,"TC-*") + COUNTIF('Xem chủ đề bài viết'!A:A,"TC-*") + COUNTIF('Xem chi tiết bài viết'!A:A,"TC-*"),"000") -> TC-071 | B19: Check business | C19: Kiểm tra button Tra cứu | D19: Kiểm tra người dùng tìm kiếm hợp lệ | E19: Người dùng đang ở form tìm kiếm | F19: 1. Nhập thông tin: - Nhập giá trị hợp lệ cho các trường thông tin còn lại 2. Click button Tra cứu | G19: HÀ NỘI - TP HCM | H19: 2. Hệ thống hiển thị thông tin chuyến đi phù hợp | I19: Pass | J19: Trần Thị Phương Thảo | K19: P1 | L19: Ready
A20: ="TC-" & TEXT( ROW()-ROW($A$7)+1 + COUNTIF('Đăng ký'!A:A,"TC-*") + COUNTIF('Đăng nhập'!A:A,"TC-*") + COUNTIF('Tìm kiếm bài viết'!A:A,"TC-*") + COUNTIF('Xem chủ đề bài viết'!A:A,"TC-*") + COUNTIF('Xem chi tiết bài viết'!A:A,"TC-*"),"000") -> TC-072 | D20: Kiểm tra tìm kiếm không có kết quả | E20: Không có chuyến phù hợp | F20: 1. Nhập tìm kiếm với dữ liệu không tồn tại 2. Click button Tra cứu | H20: 2. Hệ thống không hiển thị thông tin chuyến đi phù hợp | I20: Pass | J20: Trần Thị Phương Thảo | K20: P1 | L20: Ready

Sheet Xem danh sách chuyến tàu
A1: Module Code | B1: Xem danh sách chuyến tàu
A2: Test requirement | B2: <Brief description about requirements which are tested in this sheet>
A3: Tester
A4: Pass | B4: Fail | C4: Untested | D4: N/A | E4: Number of Test cases
A5: =COUNTIF(I6:I992,"Pass") -> 7 | B5: =COUNTIF(I6:I992,"Fail") -> 0 | C5: =E5-D5-A5-B5 -> 1 | D5: =COUNTIF(H$6:I$993,"N/A") -> 0 | E5: =COUNTA(A6:A996) -> 8
A6: Test Case ID | B6: Group Name | C6: Sub Group Name | D6: Test Case Description | E6: Precondition | F6: Test Case Procedure | G6: Test data | H6: Expected Output | I6: Result | J6: Tester | K6: Priority | L6: Status
A7: ="TC-" & TEXT( ROW()-ROW($A$7)+1 + COUNTIF('Đăng ký'!A:A,"TC-*") + COUNTIF('Đăng nhập'!A:A,"TC-*") + COUNTIF('Tìm kiếm bài viết'!A:A,"TC-*") + COUNTIF('Xem chủ đề bài viết'!A:A,"TC-*") + COUNTIF('Xem chi tiết bài viết'!A:A,"TC-*") + COUNTIF('Tìm kiếm chuyến đi'!A:A,"TC-*"),"000") -> TC-073 | B7: Access right | D7: Kiểm tra truy cập trang “Tất cả chuyến đi” | E7: Người dùng đã vào website | F7: 1. Click menu “Tất cả chuyến đi” | H7: 1. Hiển thị trang danh sách chuyến tàu | I7: Pass | J7: Trần Thị Phương Thảo | K7: P1 | L7: Ready
A8: ="TC-" & TEXT( ROW()-ROW($A$7)+1 + COUNTIF('Đăng ký'!A:A,"TC-*") + COUNTIF('Đăng nhập'!A:A,"TC-*") + COUNTIF('Tìm kiếm bài viết'!A:A,"TC-*") + COUNTIF('Xem chủ đề bài viết'!A:A,"TC-*") + COUNTIF('Xem chi tiết bài viết'!A:A,"TC-*") + COUNTIF('Tìm kiếm chuyến đi'!A:A,"TC-*"),"000") -> TC-074 | B8: UI | D8: Kiểm tra hiển thị danh sách chuyến tàu | E8: Người dung đang ở trang “Tất cả chuyến đi” | F8: 1. Quan sát danh sách | H8: 1. Hiển thị danh sách chuyến tàu từ database | I8: Pass | J8: Trần Thị Phương Thảo | K8: P1 | L8: Ready
A9: ="TC-" & TEXT( ROW()-ROW($A$7)+1 + COUNTIF('Đăng ký'!A:A,"TC-*") + COUNTIF('Đăng nhập'!A:A,"TC-*") + COUNTIF('Tìm kiếm bài viết'!A:A,"TC-*") + COUNTIF('Xem chủ đề bài viết'!A:A,"TC-*") + COUNTIF('Xem chi tiết bài viết'!A:A,"TC-*") + COUNTIF('Tìm kiếm chuyến đi'!A:A,"TC-*"),"000") -> TC-075 | D9: Kiểm tra vị trí, font chữ, size chữ, màu sắc | F9: 1. Kiểm tra vị trí, font chữ, size chữ, màu sắc | H9: 1. Hiển thị đúng theo design | I9: Pass | J9: Trần Thị Phương Thảo | K9: P2 | L9: Ready
A10: ="TC-" & TEXT( ROW()-ROW($A$7)+1 + COUNTIF('Đăng ký'!A:A,"TC-*") + COUNTIF('Đăng nhập'!A:A,"TC-*") + COUNTIF('Tìm kiếm bài viết'!A:A,"TC-*") + COUNTIF('Xem chủ đề bài viết'!A:A,"TC-*") + COUNTIF('Xem chi tiết bài viết'!A:A,"TC-*") + COUNTIF('Tìm kiếm chuyến đi'!A:A,"TC-*"),"000") -> TC-076 | D10: Kiểm tra trạng thái button | F10: 1. Kiểm tra nút “Chi tiết” | H10: 1. Button enable và click được | I10: Pass | J10: Trần Thị Phương Thảo | K10: P2 | L10: Ready
A11: ="TC-" & TEXT( ROW()-ROW($A$7)+1 + COUNTIF('Đăng ký'!A:A,"TC-*") + COUNTIF('Đăng nhập'!A:A,"TC-*") + COUNTIF('Tìm kiếm bài viết'!A:A,"TC-*") + COUNTIF('Xem chủ đề bài viết'!A:A,"TC-*") + COUNTIF('Xem chi tiết bài viết'!A:A,"TC-*") + COUNTIF('Tìm kiếm chuyến đi'!A:A,"TC-*"),"000") -> TC-077 | D11: Kiểm tra layout hiển thị | F11: 1. Quan sát UI | H11: 1. Hiển thị đúng design, không lỗi layout | I11: Pass | J11: Trần Thị Phương Thảo | K11: P2 | L11: Ready
A12: ="TC-" & TEXT( ROW()-ROW($A$7)+1 + COUNTIF('Đăng ký'!A:A,"TC-*") + COUNTIF('Đăng nhập'!A:A,"TC-*") + COUNTIF('Tìm kiếm bài viết'!A:A,"TC-*") + COUNTIF('Xem chủ đề bài viết'!A:A,"TC-*") + COUNTIF('Xem chi tiết bài viết'!A:A,"TC-*") + COUNTIF('Tìm kiếm chuyến đi'!A:A,"TC-*"),"000") -> TC-078 | B12: Check business | D12: Kiểm tra khi không có dữ liệu | E12: Hệ thống không có chuyến tàu | F12: 1. Truy cập danh sách | H12: 1. Hệ thống không hiển thị danh sách chuyến tàu | I12: Pass | J12: Trần Thị Phương Thảo | K12: P1 | L12: Ready
A13: ="TC-" & TEXT( ROW()-ROW($A$7)+1 + COUNTIF('Đăng ký'!A:A,"TC-*") + COUNTIF('Đăng nhập'!A:A,"TC-*") + COUNTIF('Tìm kiếm bài viết'!A:A,"TC-*") + COUNTIF('Xem chủ đề bài viết'!A:A,"TC-*") + COUNTIF('Xem chi tiết bài viết'!A:A,"TC-*") + COUNTIF('Tìm kiếm chuyến đi'!A:A,"TC-*"),"000") -> TC-079 | D13: Kiểm tra chuyển trang | E13: Có phân trang | F13: 1. Click trang 2 | H13: 2. Hiển thị đúng dữ liệu trang 2 | I13: Pass | J13: Trần Thị Phương Thảo | K13: P2 | L13: Ready

Sheet Xem chi tiết chuyến tàu
A1: Module Code | B1: Xem chi tiết chuyến tàu
A2: Test requirement | B2: <Brief description about requirements which are tested in this sheet>
A3: Tester
A4: Pass | B4: Fail | C4: Untested | D4: N/A | E4: Number of Test cases
A5: =COUNTIF(I6:I994,"Pass") -> 6 | B5: =COUNTIF(I6:I994,"Fail") -> 0 | C5: =E5-D5-A5-B5 -> 1 | D5: =COUNTIF(H$6:I$995,"N/A") -> 0 | E5: =COUNTA(A6:A998) -> 7
A6: Test Case ID | B6: Group Name | C6: Sub Group Name | D6: Test Case Description | E6: Precondition | F6: Test Case Procedure | G6: Test data | H6: Expected Output | I6: Result | J6: Tester | K6: Priority | L6: Status
A7: ="TC-" & TEXT( ROW()-ROW($A$7)+1 + COUNTIF('Đăng ký'!A:A,"TC-*") + COUNTIF('Đăng nhập'!A:A,"TC-*") + COUNTIF('Tìm kiếm bài viết'!A:A,"TC-*") + COUNTIF('Xem chủ đề bài viết'!A:A,"TC-*") + COUNTIF('Xem chi tiết bài viết'!A:A,"TC-*") + COUNTIF('Tìm kiếm chuyến đi'!A:A,"TC-*") + COUNTIF('Xem danh sách chuyến tàu'!A:A,"TC-*"),"000") -> TC-080 | B7: Access right | D7: Kiểm tra truy cập màn hình chi tiết chuyến tàu | E7: Người dùng đang ở danh sách chuyến tàu | F7: 1. Click “Detail” 1 chuyến tàu | H7: 1. Hiển thị màn hình chi tiết chuyến tàu | I7: Pass | J7: Trần Thị Phương Thảo | K7: P1 | L7: Ready
A8: ="TC-" & TEXT( ROW()-ROW($A$7)+1 + COUNTIF('Đăng ký'!A:A,"TC-*") + COUNTIF('Đăng nhập'!A:A,"TC-*") + COUNTIF('Tìm kiếm bài viết'!A:A,"TC-*") + COUNTIF('Xem chủ đề bài viết'!A:A,"TC-*") + COUNTIF('Xem chi tiết bài viết'!A:A,"TC-*") + COUNTIF('Tìm kiếm chuyến đi'!A:A,"TC-*") + COUNTIF('Xem danh sách chuyến tàu'!A:A,"TC-*"),"000") -> TC-081 | B8: UI | D8: Kiểm tra hiển thị đầy đủ thông tin | E8: Người dùng đang ở màn hình chi tiết | F8: 1. Quan sát thông tin | H8: 1. Hiển thị: mã chuyến, ga đi, ga đến, giờ đi, giờ đến, giá vé, số ghế | I8: Pass | J8: Trần Thị Phương Thảo | K8: P1 | L8: Ready
A9: ="TC-" & TEXT( ROW()-ROW($A$7)+1 + COUNTIF('Đăng ký'!A:A,"TC-*") + COUNTIF('Đăng nhập'!A:A,"TC-*") + COUNTIF('Tìm kiếm bài viết'!A:A,"TC-*") + COUNTIF('Xem chủ đề bài viết'!A:A,"TC-*") + COUNTIF('Xem chi tiết bài viết'!A:A,"TC-*") + COUNTIF('Tìm kiếm chuyến đi'!A:A,"TC-*") + COUNTIF('Xem danh sách chuyến tàu'!A:A,"TC-*"),"000") -> TC-082 | D9: Kiểm tra định dạng dữ liệu | F9: 1. Quan sát dữ liệu | H9: 1. Ngày giờ đúng format, giá tiền đúng định dạng | I9: Pass | J9: Trần Thị Phương Thảo | K9: P2 | L9: Ready
A10: ="TC-" & TEXT( ROW()-ROW($A$7)+1 + COUNTIF('Đăng ký'!A:A,"TC-*") + COUNTIF('Đăng nhập'!A:A,"TC-*") + COUNTIF('Tìm kiếm bài viết'!A:A,"TC-*") + COUNTIF('Xem chủ đề bài viết'!A:A,"TC-*") + COUNTIF('Xem chi tiết bài viết'!A:A,"TC-*") + COUNTIF('Tìm kiếm chuyến đi'!A:A,"TC-*") + COUNTIF('Xem danh sách chuyến tàu'!A:A,"TC-*"),"000") -> TC-083 | D10: Kiểm tra vị trí, font chữ, size chữ, màu sắc | F10: 1. Kiểm tra vị trí, font chữ, size chữ, màu sắc | H10: 1. Hiển thị đúng theo design | I10: Pass | J10: Trần Thị Phương Thảo | K10: P2 | L10: Ready
A11: ="TC-" & TEXT( ROW()-ROW($A$7)+1 + COUNTIF('Đăng ký'!A:A,"TC-*") + COUNTIF('Đăng nhập'!A:A,"TC-*") + COUNTIF('Tìm kiếm bài viết'!A:A,"TC-*") + COUNTIF('Xem chủ đề bài viết'!A:A,"TC-*") + COUNTIF('Xem chi tiết bài viết'!A:A,"TC-*") + COUNTIF('Tìm kiếm chuyến đi'!A:A,"TC-*") + COUNTIF('Xem danh sách chuyến tàu'!A:A,"TC-*"),"000") -> TC-084 | B11: Check business | D11: Kiểm tra click xem chi tiết | E11: Có danh sách chuyến tàu | F11: 1. Click “Chi tiết” 1 chuyến | H11: 2. Hiển thị thông tin chi tiết chuyến tàu | I11: Pass | J11: Trần Thị Phương Thảo | K11: P1 | L11: Ready
A12: ="TC-" & TEXT( ROW()-ROW($A$7)+1 + COUNTIF('Đăng ký'!A:A,"TC-*") + COUNTIF('Đăng nhập'!A:A,"TC-*") + COUNTIF('Tìm kiếm bài viết'!A:A,"TC-*") + COUNTIF('Xem chủ đề bài viết'!A:A,"TC-*") + COUNTIF('Xem chi tiết bài viết'!A:A,"TC-*") + COUNTIF('Tìm kiếm chuyến đi'!A:A,"TC-*") + COUNTIF('Xem danh sách chuyến tàu'!A:A,"TC-*"),"000") -> TC-085 | D12: Kiểm tra chuyển trang | E12: Có phân trang | F12: 1. Click trang 2 | H12: 2. Hiển thị đúng dữ liệu trang 2 | I12: Pass | J12: Trần Thị Phương Thảo | K12: P2 | L12: Ready

Sheet Đặt vé
A1: Module Code | B1: Đặt vé
A2: Test requirement | B2: <Brief description about requirements which are tested in this sheet>
A3: Tester
A4: Pass | B4: Fail | C4: Untested | D4: N/A | E4: Number of Test cases
A5: =COUNTIF(I6:I991,"Pass") -> 15 | B5: =COUNTIF(I6:I991,"Fail") -> 0 | C5: =E5-D5-A5-B5 -> 1 | D5: =COUNTIF(H$6:I$992,"N/A") -> 0 | E5: =COUNTA(A6:A995) -> 16
A6: Test Case ID | B6: Group Name | C6: Sub Group Name | D6: Test Case Description | E6: Precondition | F6: Test Case Procedure | G6: Test data | H6: Expected Output | I6: Result | J6: Tester | K6: Priority | L6: Status
A7: ="TC-" & TEXT( ROW()-ROW($A$7)+1 + COUNTIF('Đăng ký'!A:A,"TC-*") + COUNTIF('Đăng nhập'!A:A,"TC-*") + COUNTIF('Tìm kiếm bài viết'!A:A,"TC-*") + COUNTIF('Xem chủ đề bài viết'!A:A,"TC-*") + COUNTIF('Xem chi tiết bài viết'!A:A,"TC-*") + COUNTIF('Tìm kiếm chuyến đi'!A:A,"TC-*") + COUNTIF('Xem danh sách chuyến tàu'!A:A,"TC-*") + COUNTIF('Xem chi tiết chuyến tàu'!A:A,"TC-*"),"000") -> TC-086 | B7: Access right | D7: Kiểm tra vào màn hình đặt vé | E7: Người dùng đã đăng nhập tài khoản | F7: 1. Chọn chuyến tàu 2. Click “Book” | H7: 1. Hiển thị màn hình đặt vé với các thông tin | I7: Pass | J7: Trần Thị Phương Thảo | K7: P1 | L7: Ready
A8: ="TC-" & TEXT( ROW()-ROW($A$7)+1 + COUNTIF('Đăng ký'!A:A,"TC-*") + COUNTIF('Đăng nhập'!A:A,"TC-*") + COUNTIF('Tìm kiếm bài viết'!A:A,"TC-*") + COUNTIF('Xem chủ đề bài viết'!A:A,"TC-*") + COUNTIF('Xem chi tiết bài viết'!A:A,"TC-*") + COUNTIF('Tìm kiếm chuyến đi'!A:A,"TC-*") + COUNTIF('Xem danh sách chuyến tàu'!A:A,"TC-*") + COUNTIF('Xem chi tiết chuyến tàu'!A:A,"TC-*"),"000") -> TC-087 | D8: Kiểm tra truy cập chức năng đặt vé khi chưa đăng nhập | E8: Người dùng chưa đăng nhập tài khoản | F8: 1. Chọn chuyến tàu 2. Click “Book” | H8: 1. Hệ thống chuyển sang màn hình yêu cầu đăng nhập | I8: Pass | J8: Trần Thị Phương Thảo | K8: P1 | L8: Ready
A9: ="TC-" & TEXT( ROW()-ROW($A$7)+1 + COUNTIF('Đăng ký'!A:A,"TC-*") + COUNTIF('Đăng nhập'!A:A,"TC-*") + COUNTIF('Tìm kiếm bài viết'!A:A,"TC-*") + COUNTIF('Xem chủ đề bài viết'!A:A,"TC-*") + COUNTIF('Xem chi tiết bài viết'!A:A,"TC-*") + COUNTIF('Tìm kiếm chuyến đi'!A:A,"TC-*") + COUNTIF('Xem danh sách chuyến tàu'!A:A,"TC-*") + COUNTIF('Xem chi tiết chuyến tàu'!A:A,"TC-*"),"000") -> TC-088 | B9: UI | D9: Kiểm tra hiển thị thông tin chuyến tàu | E9: Đang ở màn hình đặt vé | F9: 1. Quan sát thông tin chuyến | H9: 1. Hiển thị đúng số lượng các item trên màn hình | I9: Pass | J9: Trần Thị Phương Thảo | K9: P2 | L9: Ready
A10: ="TC-" & TEXT( ROW()-ROW($A$7)+1 + COUNTIF('Đăng ký'!A:A,"TC-*") + COUNTIF('Đăng nhập'!A:A,"TC-*") + COUNTIF('Tìm kiếm bài viết'!A:A,"TC-*") + COUNTIF('Xem chủ đề bài viết'!A:A,"TC-*") + COUNTIF('Xem chi tiết bài viết'!A:A,"TC-*") + COUNTIF('Tìm kiếm chuyến đi'!A:A,"TC-*") + COUNTIF('Xem danh sách chuyến tàu'!A:A,"TC-*") + COUNTIF('Xem chi tiết chuyến tàu'!A:A,"TC-*"),"000") -> TC-089 | D10: Kiểm tra vị trí, font chữ, size chữ, màu sắc | F10: 1. Kiểm tra vị trí, font chữ, size chữ, màu sắc | H10: 1. Hiển thị đúng theo design | I10: Pass | J10: Trần Thị Phương Thảo | K10: P2 | L10: Ready
A11: ="TC-" & TEXT( ROW()-ROW($A$7)+1 + COUNTIF('Đăng ký'!A:A,"TC-*") + COUNTIF('Đăng nhập'!A:A,"TC-*") + COUNTIF('Tìm kiếm bài viết'!A:A,"TC-*") + COUNTIF('Xem chủ đề bài viết'!A:A,"TC-*") + COUNTIF('Xem chi tiết bài viết'!A:A,"TC-*") + COUNTIF('Tìm kiếm chuyến đi'!A:A,"TC-*") + COUNTIF('Xem danh sách chuyến tàu'!A:A,"TC-*") + COUNTIF('Xem chi tiết chuyến tàu'!A:A,"TC-*"),"000") -> TC-090 | D11: Kiểm tra trạng thái | F11: 1. Kiểm tra trạng thái các item | H11: 1. Các item đều ở trạng thái enable | I11: Pass | J11: Trần Thị Phương Thảo | K11: P2 | L11: Ready
A12: ="TC-" & TEXT( ROW()-ROW($A$7)+1 + COUNTIF('Đăng ký'!A:A,"TC-*") + COUNTIF('Đăng nhập'!A:A,"TC-*") + COUNTIF('Tìm kiếm bài viết'!A:A,"TC-*") + COUNTIF('Xem chủ đề bài viết'!A:A,"TC-*") + COUNTIF('Xem chi tiết bài viết'!A:A,"TC-*") + COUNTIF('Tìm kiếm chuyến đi'!A:A,"TC-*") + COUNTIF('Xem danh sách chuyến tàu'!A:A,"TC-*") + COUNTIF('Xem chi tiết chuyến tàu'!A:A,"TC-*"),"000") -> TC-091 | D12: Kiểm tra giá trị default | F12: 1. Kiểm tra các giá trị default | H12: 1. Các text box đều hiển thị trắng | I12: Pass | J12: Trần Thị Phương Thảo | K12: P2 | L12: Ready
A13: ="TC-" & TEXT( ROW()-ROW($A$7)+1 + COUNTIF('Đăng ký'!A:A,"TC-*") + COUNTIF('Đăng nhập'!A:A,"TC-*") + COUNTIF('Tìm kiếm bài viết'!A:A,"TC-*") + COUNTIF('Xem chủ đề bài viết'!A:A,"TC-*") + COUNTIF('Xem chi tiết bài viết'!A:A,"TC-*") + COUNTIF('Tìm kiếm chuyến đi'!A:A,"TC-*") + COUNTIF('Xem danh sách chuyến tàu'!A:A,"TC-*") + COUNTIF('Xem chi tiết chuyến tàu'!A:A,"TC-*"),"000") -> TC-092 | D13: Kiểm tra dropdown Gender | F13: 1. Click dropdown | H13: 1. Hiển thị danh sách (Male/Female) | I13: Pass | J13: Trần Thị Phương Thảo | K13: P2 | L13: Ready
A14: ="TC-" & TEXT( ROW()-ROW($A$7)+1 + COUNTIF('Đăng ký'!A:A,"TC-*") + COUNTIF('Đăng nhập'!A:A,"TC-*") + COUNTIF('Tìm kiếm bài viết'!A:A,"TC-*") + COUNTIF('Xem chủ đề bài viết'!A:A,"TC-*") + COUNTIF('Xem chi tiết bài viết'!A:A,"TC-*") + COUNTIF('Tìm kiếm chuyến đi'!A:A,"TC-*") + COUNTIF('Xem danh sách chuyến tàu'!A:A,"TC-*") + COUNTIF('Xem chi tiết chuyến tàu'!A:A,"TC-*"),"000") -> TC-093 | D14: Kiểm tra dropdown National | F14: 1. Click dropdown | H14: 1. Hiển thị danh sách quốc gia | I14: Pass | J14: Trần Thị Phương Thảo | K14: P2 | L14: Ready
A15: ="TC-" & TEXT( ROW()-ROW($A$7)+1 + COUNTIF('Đăng ký'!A:A,"TC-*") + COUNTIF('Đăng nhập'!A:A,"TC-*") + COUNTIF('Tìm kiếm bài viết'!A:A,"TC-*") + COUNTIF('Xem chủ đề bài viết'!A:A,"TC-*") + COUNTIF('Xem chi tiết bài viết'!A:A,"TC-*") + COUNTIF('Tìm kiếm chuyến đi'!A:A,"TC-*") + COUNTIF('Xem danh sách chuyến tàu'!A:A,"TC-*") + COUNTIF('Xem chi tiết chuyến tàu'!A:A,"TC-*"),"000") -> TC-094 | B15: Check Validation | C15: Passenger | D15: Kiểm tra không nhập tên hành khách | E15: Đang ở màn hình đặt vé | F15: 1. Nhập thông tin: - Passenger: bỏ trống - Nhập giá trị hợp lệ cho các trường thông tin còn lại 2. Click button Next | H15: 2. Hệ thống hiển thị thông báo lỗi: "Please fill out this field" | I15: Pass | J15: Trần Thị Phương Thảo | K15: P1 | L15: Ready
A16: ="TC-" & TEXT( ROW()-ROW($A$7)+1 + COUNTIF('Đăng ký'!A:A,"TC-*") + COUNTIF('Đăng nhập'!A:A,"TC-*") + COUNTIF('Tìm kiếm bài viết'!A:A,"TC-*") + COUNTIF('Xem chủ đề bài viết'!A:A,"TC-*") + COUNTIF('Xem chi tiết bài viết'!A:A,"TC-*") + COUNTIF('Tìm kiếm chuyến đi'!A:A,"TC-*") + COUNTIF('Xem danh sách chuyến tàu'!A:A,"TC-*") + COUNTIF('Xem chi tiết chuyến tàu'!A:A,"TC-*"),"000") -> TC-095 | C16: Email | D16: Không nhập email | F16: 1. Nhập thông tin: - Email: bỏ trống - Nhập giá trị hợp lệ cho các trường thông tin còn lại 2. Click button Next | H16: 2. Hệ thống hiển thị thông báo lỗi: "Please fill out this field" | I16: Pass | J16: Trần Thị Phương Thảo | K16: P1 | L16: Ready
A17: ="TC-" & TEXT( ROW()-ROW($A$7)+1 + COUNTIF('Đăng ký'!A:A,"TC-*") + COUNTIF('Đăng nhập'!A:A,"TC-*") + COUNTIF('Tìm kiếm bài viết'!A:A,"TC-*") + COUNTIF('Xem chủ đề bài viết'!A:A,"TC-*") + COUNTIF('Xem chi tiết bài viết'!A:A,"TC-*") + COUNTIF('Tìm kiếm chuyến đi'!A:A,"TC-*") + COUNTIF('Xem danh sách chuyến tàu'!A:A,"TC-*") + COUNTIF('Xem chi tiết chuyến tàu'!A:A,"TC-*"),"000") -> TC-096 | D17: Kiểm tra nhập email sai định dạng | F17: 1. Nhập thông tin: - Email: thao.com - Nhập giá trị hợp lệ cho các trường thông tin còn lại 2. Click button Next | G17: Email: thao.com | H17: 2. Hệ thống hiển thị thông báo lỗi: “Please include an ‘@’ in the email address. ‘thao.com’ is missing an ‘@’” | I17: Pass | J17: Trần Thị Phương Thảo | K17: P1 | L17: Ready
A18: ="TC-" & TEXT( ROW()-ROW($A$7)+1 + COUNTIF('Đăng ký'!A:A,"TC-*") + COUNTIF('Đăng nhập'!A:A,"TC-*") + COUNTIF('Tìm kiếm bài viết'!A:A,"TC-*") + COUNTIF('Xem chủ đề bài viết'!A:A,"TC-*") + COUNTIF('Xem chi tiết bài viết'!A:A,"TC-*") + COUNTIF('Tìm kiếm chuyến đi'!A:A,"TC-*") + COUNTIF('Xem danh sách chuyến tàu'!A:A,"TC-*") + COUNTIF('Xem chi tiết chuyến tàu'!A:A,"TC-*"),"000") -> TC-097 | C18: Phone | D18: Kiểm tra không nhập số phone | F18: 1. Nhập thông tin: - Phone: bỏ trống - Nhập giá trị hợp lệ cho các trường thông tin còn lại 2. Click button Next | H18: 2. Hệ thống hiển thị thông báo lỗi: "Please fill out this field" | I18: Pass | J18: Trần Thị Phương Thảo | K18: P1 | L18: Ready
A19: ="TC-" & TEXT( ROW()-ROW($A$7)+1 + COUNTIF('Đăng ký'!A:A,"TC-*") + COUNTIF('Đăng nhập'!A:A,"TC-*") + COUNTIF('Tìm kiếm bài viết'!A:A,"TC-*") + COUNTIF('Xem chủ đề bài viết'!A:A,"TC-*") + COUNTIF('Xem chi tiết bài viết'!A:A,"TC-*") + COUNTIF('Tìm kiếm chuyến đi'!A:A,"TC-*") + COUNTIF('Xem danh sách chuyến tàu'!A:A,"TC-*") + COUNTIF('Xem chi tiết chuyến tàu'!A:A,"TC-*"),"000") -> TC-098 | C19: Message | D19: Kiểm tra không nhập Message | F19: 1. Nhập thông tin: - Message: bỏ trống - Nhập giá trị hợp lệ cho các trường thông tin còn lại 2. Click button Next | H19: 2. Hệ thống hiển thị thông báo lỗi: "Please fill out this field" | I19: Pass | J19: Trần Thị Phương Thảo | K19: P1 | L19: Ready
A20: ="TC-" & TEXT( ROW()-ROW($A$7)+1 + COUNTIF('Đăng ký'!A:A,"TC-*") + COUNTIF('Đăng nhập'!A:A,"TC-*") + COUNTIF('Tìm kiếm bài viết'!A:A,"TC-*") + COUNTIF('Xem chủ đề bài viết'!A:A,"TC-*") + COUNTIF('Xem chi tiết bài viết'!A:A,"TC-*") + COUNTIF('Tìm kiếm chuyến đi'!A:A,"TC-*") + COUNTIF('Xem danh sách chuyến tàu'!A:A,"TC-*") + COUNTIF('Xem chi tiết chuyến tàu'!A:A,"TC-*"),"000") -> TC-099 | D20: Kiểm tra khách hàng đặt vé bỏ trống không nhập tất cả thông tin | F20: 1.Nhập thông tin: Bỏ trống 2. Click button Next | H20: 2. Hệ thống hiển thị thông báo lỗi: "Please fill out this field" | I20: Pass | J20: Trần Thị Phương Thảo | K20: P1 | L20: Ready
A21: ="TC-" & TEXT( ROW()-ROW($A$7)+1 + COUNTIF('Đăng ký'!A:A,"TC-*") + COUNTIF('Đăng nhập'!A:A,"TC-*") + COUNTIF('Tìm kiếm bài viết'!A:A,"TC-*") + COUNTIF('Xem chủ đề bài viết'!A:A,"TC-*") + COUNTIF('Xem chi tiết bài viết'!A:A,"TC-*") + COUNTIF('Tìm kiếm chuyến đi'!A:A,"TC-*") + COUNTIF('Xem danh sách chuyến tàu'!A:A,"TC-*") + COUNTIF('Xem chi tiết chuyến tàu'!A:A,"TC-*"),"000") -> TC-100 | D21: Đặt vé thành công | F21: 1. Nhập đầy đủ thông tin hợp lệ 2. Click Next | H21: 2. Hệ thống đặt vé thành công thông và hiển thị chi tiết vé, thông tin được lưu trong database | I21: Pass | J21: Trần Thị Phương Thảo | K21: P1 | L21: Ready

Sheet Xem lịch sử đặt vé
A1: Module Code | B1: Xem lịch sử đặt vé
A2: Test requirement | B2: <Brief description about requirements which are tested in this sheet>
A3: Tester
A4: Pass | B4: Fail | C4: Untested | D4: N/A | E4: Number of Test cases
A5: =COUNTIF(I6:I995,"Pass") -> 10 | B5: =COUNTIF(I6:I995,"Fail") -> 0 | C5: =E5-D5-A5-B5 -> 1 | D5: =COUNTIF(H$6:I$996,"N/A") -> 0 | E5: =COUNTA(A6:A999) -> 11
A6: Test Case ID | B6: Group Name | C6: Sub Group Name | D6: Test Case Description | E6: Precondition | F6: Test Case Procedure | G6: Test data | H6: Expected Output | I6: Result | J6: Tester | K6: Priority | L6: Status
A7: ="TC-" & TEXT( ROW()-ROW($A$7)+1 + COUNTIF('Đăng ký'!A:A,"TC-*") + COUNTIF('Đăng nhập'!A:A,"TC-*") + COUNTIF('Tìm kiếm bài viết'!A:A,"TC-*") + COUNTIF('Xem chủ đề bài viết'!A:A,"TC-*") + COUNTIF('Xem chi tiết bài viết'!A:A,"TC-*") + COUNTIF('Tìm kiếm chuyến đi'!A:A,"TC-*") + COUNTIF('Xem danh sách chuyến tàu'!A:A,"TC-*") + COUNTIF('Xem chi tiết chuyến tàu'!A:A,"TC-*") + COUNTIF('Đặt vé'!A:A,"TC-*"),"000") -> TC-101 | B7: Access right | D7: Kiểm tra truy cập lịch sử vé khi chưa đăng nhập | E7: Người dùng chưa đăng nhập tài khoản | F7: 1. Truy cập website 2. Click “Tài khoản” | H7: 1. Chuyển hướng đến trang đăng nhập | I7: Pass | J7: Trần Thị Phương Thảo | K7: P1 | L7: Ready
A8: ="TC-" & TEXT( ROW()-ROW($A$7)+1 + COUNTIF('Đăng ký'!A:A,"TC-*") + COUNTIF('Đăng nhập'!A:A,"TC-*") + COUNTIF('Tìm kiếm bài viết'!A:A,"TC-*") + COUNTIF('Xem chủ đề bài viết'!A:A,"TC-*") + COUNTIF('Xem chi tiết bài viết'!A:A,"TC-*") + COUNTIF('Tìm kiếm chuyến đi'!A:A,"TC-*") + COUNTIF('Xem danh sách chuyến tàu'!A:A,"TC-*") + COUNTIF('Xem chi tiết chuyến tàu'!A:A,"TC-*") + COUNTIF('Đặt vé'!A:A,"TC-*"),"000") -> TC-102 | D8: Kiểm tra truy cập lịch sử vé khi đã đăng nhập | E8: Người dùng đã đăng nhập tài khoản | F8: 1. Truy cập website 2. Click “Tài khoản” | H8: 1. Hiển thị danh sách vé đã đặt | I8: Pass | J8: Trần Thị Phương Thảo | K8: P1 | L8: Ready
A9: ="TC-" & TEXT( ROW()-ROW($A$7)+1 + COUNTIF('Đăng ký'!A:A,"TC-*") + COUNTIF('Đăng nhập'!A:A,"TC-*") + COUNTIF('Tìm kiếm bài viết'!A:A,"TC-*") + COUNTIF('Xem chủ đề bài viết'!A:A,"TC-*") + COUNTIF('Xem chi tiết bài viết'!A:A,"TC-*") + COUNTIF('Tìm kiếm chuyến đi'!A:A,"TC-*") + COUNTIF('Xem danh sách chuyến tàu'!A:A,"TC-*") + COUNTIF('Xem chi tiết chuyến tàu'!A:A,"TC-*") + COUNTIF('Đặt vé'!A:A,"TC-*"),"000") -> TC-103 | B9: UI | D9: Kiểm tra hiển thị danh sách vé | E9: Đã đăng nhập | F9: 1. Vào “Tài khoản” | H9: 1. Hiển thị đúng số lượng các item trên màn hình | I9: Pass | J9: Trần Thị Phương Thảo | K9: P2 | L9: Ready
A10: ="TC-" & TEXT( ROW()-ROW($A$7)+1 + COUNTIF('Đăng ký'!A:A,"TC-*") + COUNTIF('Đăng nhập'!A:A,"TC-*") + COUNTIF('Tìm kiếm bài viết'!A:A,"TC-*") + COUNTIF('Xem chủ đề bài viết'!A:A,"TC-*") + COUNTIF('Xem chi tiết bài viết'!A:A,"TC-*") + COUNTIF('Tìm kiếm chuyến đi'!A:A,"TC-*") + COUNTIF('Xem danh sách chuyến tàu'!A:A,"TC-*") + COUNTIF('Xem chi tiết chuyến tàu'!A:A,"TC-*") + COUNTIF('Đặt vé'!A:A,"TC-*"),"000") -> TC-104 | D10: Kiểm tra hiển thị thông tin vé | F10: 1. Quan sát danh sách | H10: 1. Hiển thị đúng theo design | I10: Pass | J10: Trần Thị Phương Thảo | K10: P2 | L10: Ready
A11: ="TC-" & TEXT( ROW()-ROW($A$7)+1 + COUNTIF('Đăng ký'!A:A,"TC-*") + COUNTIF('Đăng nhập'!A:A,"TC-*") + COUNTIF('Tìm kiếm bài viết'!A:A,"TC-*") + COUNTIF('Xem chủ đề bài viết'!A:A,"TC-*") + COUNTIF('Xem chi tiết bài viết'!A:A,"TC-*") + COUNTIF('Tìm kiếm chuyến đi'!A:A,"TC-*") + COUNTIF('Xem danh sách chuyến tàu'!A:A,"TC-*") + COUNTIF('Xem chi tiết chuyến tàu'!A:A,"TC-*") + COUNTIF('Đặt vé'!A:A,"TC-*"),"000") -> TC-105 | D11: Kiểm tra font, màu sắc, vị trí | E11: Đã vào trang | F11: 1. Quan sát UI | H11: 1. Hiển thị đúng design | I11: Pass | J11: Trần Thị Phương Thảo | K11: P2 | L11: Ready
A12: ="TC-" & TEXT( ROW()-ROW($A$7)+1 + COUNTIF('Đăng ký'!A:A,"TC-*") + COUNTIF('Đăng nhập'!A:A,"TC-*") + COUNTIF('Tìm kiếm bài viết'!A:A,"TC-*") + COUNTIF('Xem chủ đề bài viết'!A:A,"TC-*") + COUNTIF('Xem chi tiết bài viết'!A:A,"TC-*") + COUNTIF('Tìm kiếm chuyến đi'!A:A,"TC-*") + COUNTIF('Xem danh sách chuyến tàu'!A:A,"TC-*") + COUNTIF('Xem chi tiết chuyến tàu'!A:A,"TC-*") + COUNTIF('Đặt vé'!A:A,"TC-*"),"000") -> TC-106 | D12: Kiểm tra trạng thái button | F12: 1. Kiểm tra nút “Detail Order” | H12: 1. Button enable và click được | I12: Pass | J12: Trần Thị Phương Thảo | K12: P2 | L12: Ready
A13: ="TC-" & TEXT( ROW()-ROW($A$7)+1 + COUNTIF('Đăng ký'!A:A,"TC-*") + COUNTIF('Đăng nhập'!A:A,"TC-*") + COUNTIF('Tìm kiếm bài viết'!A:A,"TC-*") + COUNTIF('Xem chủ đề bài viết'!A:A,"TC-*") + COUNTIF('Xem chi tiết bài viết'!A:A,"TC-*") + COUNTIF('Tìm kiếm chuyến đi'!A:A,"TC-*") + COUNTIF('Xem danh sách chuyến tàu'!A:A,"TC-*") + COUNTIF('Xem chi tiết chuyến tàu'!A:A,"TC-*") + COUNTIF('Đặt vé'!A:A,"TC-*"),"000") -> TC-107 | B13: Check Validation | D13: Kiểm tra khi không có vé | E13: Đã vào trang | F13: 1. Vào “Tài khoản” | H13: 2. Hệ thống không hiển thị danh sách vé đã đặt | I13: Pass | J13: Trần Thị Phương Thảo | K13: P1 | L13: Ready
A14: ="TC-" & TEXT( ROW()-ROW($A$7)+1 + COUNTIF('Đăng ký'!A:A,"TC-*") + COUNTIF('Đăng nhập'!A:A,"TC-*") + COUNTIF('Tìm kiếm bài viết'!A:A,"TC-*") + COUNTIF('Xem chủ đề bài viết'!A:A,"TC-*") + COUNTIF('Xem chi tiết bài viết'!A:A,"TC-*") + COUNTIF('Tìm kiếm chuyến đi'!A:A,"TC-*") + COUNTIF('Xem danh sách chuyến tàu'!A:A,"TC-*") + COUNTIF('Xem chi tiết chuyến tàu'!A:A,"TC-*") + COUNTIF('Đặt vé'!A:A,"TC-*"),"000") -> TC-108 | D14: Kiểm tra định dạng dữ liệu | F14: 1. Quan sát dữ liệu | H14: 2. Hệ thống hiển thị đúng dữ liệu | I14: Pass | J14: Trần Thị Phương Thảo | K14: P1 | L14: Ready
A15: ="TC-" & TEXT( ROW()-ROW($A$7)+1 + COUNTIF('Đăng ký'!A:A,"TC-*") + COUNTIF('Đăng nhập'!A:A,"TC-*") + COUNTIF('Tìm kiếm bài viết'!A:A,"TC-*") + COUNTIF('Xem chủ đề bài viết'!A:A,"TC-*") + COUNTIF('Xem chi tiết bài viết'!A:A,"TC-*") + COUNTIF('Tìm kiếm chuyến đi'!A:A,"TC-*") + COUNTIF('Xem danh sách chuyến tàu'!A:A,"TC-*") + COUNTIF('Xem chi tiết chuyến tàu'!A:A,"TC-*") + COUNTIF('Đặt vé'!A:A,"TC-*"),"000") -> TC-109 | B15: Check business | D15: Kiểm tra hiển thị danh sách vé từ DB | E15: Có dữ liệu vé | F15: 1. Vào “Tài khoản” | H15: 2. Dữ liệu lấy từ DAT_VE và hiển thị đúng | I15: Pass | J15: Trần Thị Phương Thảo | K15: P1 | L15: Ready
A16: ="TC-" & TEXT( ROW()-ROW($A$7)+1 + COUNTIF('Đăng ký'!A:A,"TC-*") + COUNTIF('Đăng nhập'!A:A,"TC-*") + COUNTIF('Tìm kiếm bài viết'!A:A,"TC-*") + COUNTIF('Xem chủ đề bài viết'!A:A,"TC-*") + COUNTIF('Xem chi tiết bài viết'!A:A,"TC-*") + COUNTIF('Tìm kiếm chuyến đi'!A:A,"TC-*") + COUNTIF('Xem danh sách chuyến tàu'!A:A,"TC-*") + COUNTIF('Xem chi tiết chuyến tàu'!A:A,"TC-*") + COUNTIF('Đặt vé'!A:A,"TC-*"),"000") -> TC-110 | D16: Xem chi tiết vé | E16: Có danh sách vé | F16: 1. Click “Detail Order” | H16: 2. Hiển thị chi tiết từ DAT_VE và CHI_TIET_VE | I16: Pass | J16: Trần Thị Phương Thảo | K16: P1 | L16: Ready

Sheet Hủy vé
A1: Module Code | B1: Hủy vé
A2: Test requirement | B2: <Brief description about requirements which are tested in this sheet>
A3: Tester
A4: Pass | B4: Fail | C4: Untested | D4: N/A | E4: Number of Test cases
A5: =COUNTIF(I6:I993,"Pass") -> 5 | B5: =COUNTIF(I6:I993,"Fail") -> 2 | C5: =E5-D5-A5-B5 -> 1 | D5: =COUNTIF(H$6:I$994,"N/A") -> 0 | E5: =COUNTA(A6:A997) -> 8
A6: Test Case ID | B6: Group Name | C6: Sub Group Name | D6: Test Case Description | E6: Precondition | F6: Test Case Procedure | G6: Test data | H6: Expected Output | I6: Result | J6: Tester | K6: Priority | L6: Status
